Grade: 45.00/50.00

2 Deduction(s):

--------------
#1: 2.00 points
Failing test: test_vectorize_2: 
        @points=2
        
Traceback (most recent call last):
  File "/usr/local/lib/python3.7/site-packages/pandas/core/indexes/base.py", line 3078, in get_loc
    return self._engine.get_loc(key)
  File "pandas/_libs/index.pyx", line 140, in pandas._libs.index.IndexEngine.get_loc
  File "pandas/_libs/index.pyx", line 162, in pandas._libs.index.IndexEngine.get_loc
  File "pandas/_libs/hashtable_class_helper.pxi", line 1492, in pandas._libs.hashtable.PyObjectHashTable.get_item
  File "pandas/_libs/hashtable_class_helper.pxi", line 1500, in pandas._libs.hashtable.PyObjectHashTable.get_item
KeyError: 'features'

During handling of the above exception, another exception occurred:

Traceback (most recent call last):
  File "../assignments-sol/a3/a3_test.py", line 56, in test_vectorize_2
    row0 = movies['features'].tolist()[0]
  File "/usr/local/lib/python3.7/site-packages/pandas/core/frame.py", line 2688, in __getitem__
    return self._getitem_column(key)
  File "/usr/local/lib/python3.7/site-packages/pandas/core/frame.py", line 2695, in _getitem_column
    return self._get_item_cache(key)
  File "/usr/local/lib/python3.7/site-packages/pandas/core/generic.py", line 2489, in _get_item_cache
    values = self._data.get(item)
  File "/usr/local/lib/python3.7/site-packages/pandas/core/internals.py", line 4115, in get
    loc = self.items.get_loc(item)
  File "/usr/local/lib/python3.7/site-packages/pandas/core/indexes/base.py", line 3080, in get_loc
    return self._engine.get_loc(self._maybe_cast_indexer(key))
  File "pandas/_libs/index.pyx", line 140, in pandas._libs.index.IndexEngine.get_loc
  File "pandas/_libs/index.pyx", line 162, in pandas._libs.index.IndexEngine.get_loc
  File "pandas/_libs/hashtable_class_helper.pxi", line 1492, in pandas._libs.hashtable.PyObjectHashTable.get_item
  File "pandas/_libs/hashtable_class_helper.pxi", line 1500, in pandas._libs.hashtable.PyObjectHashTable.get_item
KeyError: 'features'

source:
    def test_vectorize_2(self):
         """
         @points=2
         """
         movies = pd.DataFrame([[123, 'horror|horror|romance|romance|romance',
                                 ['horror', 'horror', 'romance', 'romance', 'romance']],
                                [456, 'romance', ['romance']]], columns=['movieId', 'genres', 'tokens'])
         movies = add_titles(movies)
         movies, vocab = featurize(movies)
         row0 = movies['features'].tolist()[0]
         self.assertEqual('%.2f' % round(max(list(row0.data)), 2),
                             '0.20')
         self.assertEqual(round(min(row0.toarray()[0]), 1),
                             0.0)
--------------

--------------
#2: 3.00 points
Failing test: test_vectorize_3: 
        @points=3
        
Traceback (most recent call last):
  File "/usr/local/lib/python3.7/site-packages/pandas/core/indexes/base.py", line 3078, in get_loc
    return self._engine.get_loc(key)
  File "pandas/_libs/index.pyx", line 140, in pandas._libs.index.IndexEngine.get_loc
  File "pandas/_libs/index.pyx", line 162, in pandas._libs.index.IndexEngine.get_loc
  File "pandas/_libs/hashtable_class_helper.pxi", line 1492, in pandas._libs.hashtable.PyObjectHashTable.get_item
  File "pandas/_libs/hashtable_class_helper.pxi", line 1500, in pandas._libs.hashtable.PyObjectHashTable.get_item
KeyError: 'features'

During handling of the above exception, another exception occurred:

Traceback (most recent call last):
  File "../assignments-sol/a3/a3_test.py", line 71, in test_vectorize_3
    row1 = movies['features'].tolist()[1]
  File "/usr/local/lib/python3.7/site-packages/pandas/core/frame.py", line 2688, in __getitem__
    return self._getitem_column(key)
  File "/usr/local/lib/python3.7/site-packages/pandas/core/frame.py", line 2695, in _getitem_column
    return self._get_item_cache(key)
  File "/usr/local/lib/python3.7/site-packages/pandas/core/generic.py", line 2489, in _get_item_cache
    values = self._data.get(item)
  File "/usr/local/lib/python3.7/site-packages/pandas/core/internals.py", line 4115, in get
    loc = self.items.get_loc(item)
  File "/usr/local/lib/python3.7/site-packages/pandas/core/indexes/base.py", line 3080, in get_loc
    return self._engine.get_loc(self._maybe_cast_indexer(key))
  File "pandas/_libs/index.pyx", line 140, in pandas._libs.index.IndexEngine.get_loc
  File "pandas/_libs/index.pyx", line 162, in pandas._libs.index.IndexEngine.get_loc
  File "pandas/_libs/hashtable_class_helper.pxi", line 1492, in pandas._libs.hashtable.PyObjectHashTable.get_item
  File "pandas/_libs/hashtable_class_helper.pxi", line 1500, in pandas._libs.hashtable.PyObjectHashTable.get_item
KeyError: 'features'

source:
    def test_vectorize_3(self):
         """
         @points=3
         """
         movies = pd.DataFrame([[123, 'horror|horror|romance|romance|romance',
                                 ['horror', 'horror', 'romance', 'romance', 'romance']],
                                [456, 'romance', ['romance']]], columns=['movieId', 'genres', 'tokens'])
         movies = add_titles(movies)
         movies, vocab = featurize(movies)
         row1 = movies['features'].tolist()[1]
         self.assertEqual(round(max(list(row1.toarray()[0])), 1),
                          0.0)
--------------

